[E 250410 12:07:36 smartConnect:221] Error occurred while making a POST request to https://apiconnect.angelone.in/rest/secure/angelbroking/order/v1/searchScrip. Headers: {'Content-type': 'application/json', 'X-ClientLocalIP': '127.0.0.1', 'X-ClientPublicIP': '106.193.147.98', 'X-MACAddress': 'fa:15:15:31:b2:20', 'Accept': 'application/json', 'X-PrivateKey': 'vhAupRK9', 'X-UserType': 'USER', 'X-SourceID': 'WEB', 'Authorization': 'Bearer eyJhbGciOiJIUzUxMiJ9.eyJ1c2VybmFtZSI6Ikw1MjEyODY3MyIsInJvbGVzIjowLCJ1c2VydHlwZSI6IlVTRVIiLCJ0b2tlbiI6ImV5SmhiR2NpT2lKU1V6STFOaUlzSW5SNWNDSTZJa3BYVkNKOS5leUoxYzJWeVgzUjVjR1VpT2lKamJHbGxiblFpTENKMGIydGxibDkwZVhCbElqb2lkSEpoWkdWZllXTmpaWE56WDNSdmEyVnVJaXdpWjIxZmFXUWlPakV5TENKemIzVnlZMlVpT2lJeklpd2laR1YyYVdObFgybGtJam9pTjJNMk56STVaV1l0T1dFd1lTMHpNakF6TFRneFpHWXROVGczWTJNM05qUmtaRGcySWl3aWEybGtJam9pZEhKaFpHVmZhMlY1WDNZeUlpd2liMjF1WlcxaGJtRm5aWEpwWkNJNk1USXNJbkJ5YjJSMVkzUnpJanA3SW1SbGJXRjBJanA3SW5OMFlYUjFjeUk2SW1GamRHbDJaU0o5TENKdFppSTZleUp6ZEdGMGRYTWlPaUpoWTNScGRtVWlmWDBzSW1semN5STZJblJ5WVdSbFgyeHZaMmx1WDNObGNuWnBZMlVpTENKemRXSWlPaUpNTlRJeE1qZzJOek1pTENKbGVIQWlPakUzTkRRek5USTRNekVzSW01aVppSTZNVGMwTkRJMk5qSTFNU3dpYVdGMElqb3hOelEwTWpZMk1qVXhMQ0pxZEdraU9pSmxZelUyWVRGaVlpMHhZVE01TFRSbE5Ua3RZalE1T1MxaVpUTmpPVGt4WkRWaU9EZ2lMQ0pVYjJ0bGJpSTZJaUo5LnFXT2xWQTU3TFFGbC1SNlc0QUF6eldsc2dURWZKOHREeUZlLUt6Sjl0V1Y1UHc5Rk9rcTZIbko4SGtoQ0ZvZjBKbWtxVWM4SVk4aHljNzRPeXNFeXoyUzJxU2RmTGY5R1RLNVpHeTdwWDhFdzNWc0lHVWd5NHp0U2RBRFhuUG14NWNZTTRwcXpfaG9fTk1VQ01xeDFUVkFOSmx4OUUwRTBYN2lwVUYteFV1NCIsIkFQSS1LRVkiOiJ2aEF1cFJLOSIsImlhdCI6MTc0NDI2NjQzMiwiZXhwIjoxNzQ0MzUyODMxfQ.UFVQqaCdj3B5Dt1XVGTOjWPrrMeEg6wYTX1MJRSfMSmK9wsiWjjYXMz2p46cmLiKSf-MSUiWZ9vQjZOC8HxAEg'}, Request: {'exchange': 'NSE', 'searchscrip': 'TATAMOTORS-EQ'}, Response: HTTPSConnectionPool(host='apiconnect.angelone.in', port=443): Read timed out. (read timeout=7)
[E 250410 12:07:36 AngleSmartAPI:74] Logout failed: HTTPSConnectionPool(host='apiconnect.angelone.in', port=443): Read timed out. (read timeout=7)
    Traceback (most recent call last):
      File "/Users/hmaheshwari/Documents/PROJECTS/TradingView/.venv/lib/python3.13/site-packages/urllib3/connectionpool.py", line 464, in _make_request
        self._validate_conn(conn)
        ~~~~~~~~~~~~~~~~~~~^^^^^^
      File "/Users/hmaheshwari/Documents/PROJECTS/TradingView/.venv/lib/python3.13/site-packages/urllib3/connectionpool.py", line 1093, in _validate_conn
        conn.connect()
        ~~~~~~~~~~~~^^
      File "/Users/hmaheshwari/Documents/PROJECTS/TradingView/.venv/lib/python3.13/site-packages/urllib3/connection.py", line 741, in connect
        sock_and_verified = _ssl_wrap_socket_and_match_hostname(
            sock=sock,
        ...<14 lines>...
            assert_fingerprint=self.assert_fingerprint,
        )
      File "/Users/hmaheshwari/Documents/PROJECTS/TradingView/.venv/lib/python3.13/site-packages/urllib3/connection.py", line 920, in _ssl_wrap_socket_and_match_hostname
        ssl_sock = ssl_wrap_socket(
            sock=sock,
        ...<8 lines>...
            tls_in_tls=tls_in_tls,
        )
      File "/Users/hmaheshwari/Documents/PROJECTS/TradingView/.venv/lib/python3.13/site-packages/urllib3/util/ssl_.py", line 460, in ssl_wrap_socket
        ssl_sock = _ssl_wrap_socket_impl(sock, context, tls_in_tls, server_hostname)
      File "/Users/hmaheshwari/Documents/PROJECTS/TradingView/.venv/lib/python3.13/site-packages/urllib3/util/ssl_.py", line 504, in _ssl_wrap_socket_impl
        return ssl_context.wrap_socket(sock, server_hostname=server_hostname)
               ~~~~~~~~~~~~~~~~~~~~~~~^^^^^^^^^^^^^^^^^^^^^^^^^^^^^^^^^^^^^^^
      File "/opt/homebrew/Cellar/python@3.13/3.13.2/Frameworks/Python.framework/Versions/3.13/lib/python3.13/ssl.py", line 455, in wrap_socket
        return self.sslsocket_class._create(
               ~~~~~~~~~~~~~~~~~~~~~~~~~~~~^
            sock=sock,
            ^^^^^^^^^^
        ...<5 lines>...
            session=session
            ^^^^^^^^^^^^^^^
        )
        ^
      File "/opt/homebrew/Cellar/python@3.13/3.13.2/Frameworks/Python.framework/Versions/3.13/lib/python3.13/ssl.py", line 1076, in _create
        self.do_handshake()
        ~~~~~~~~~~~~~~~~~^^
      File "/opt/homebrew/Cellar/python@3.13/3.13.2/Frameworks/Python.framework/Versions/3.13/lib/python3.13/ssl.py", line 1372, in do_handshake
        self._sslobj.do_handshake()
        ~~~~~~~~~~~~~~~~~~~~~~~~~^^
    TimeoutError: _ssl.c:1011: The handshake operation timed out
    
    The above exception was the direct cause of the following exception:
    
    Traceback (most recent call last):
      File "/Users/hmaheshwari/Documents/PROJECTS/TradingView/.venv/lib/python3.13/site-packages/requests/adapters.py", line 667, in send
        resp = conn.urlopen(
            method=request.method,
        ...<9 lines>...
            chunked=chunked,
        )
      File "/Users/hmaheshwari/Documents/PROJECTS/TradingView/.venv/lib/python3.13/site-packages/urllib3/connectionpool.py", line 841, in urlopen
        retries = retries.increment(
            method, url, error=new_e, _pool=self, _stacktrace=sys.exc_info()[2]
        )
      File "/Users/hmaheshwari/Documents/PROJECTS/TradingView/.venv/lib/python3.13/site-packages/urllib3/util/retry.py", line 474, in increment
        raise reraise(type(error), error, _stacktrace)
              ~~~~~~~^^^^^^^^^^^^^^^^^^^^^^^^^^^^^^^^^
      File "/Users/hmaheshwari/Documents/PROJECTS/TradingView/.venv/lib/python3.13/site-packages/urllib3/util/util.py", line 39, in reraise
        raise value
      File "/Users/hmaheshwari/Documents/PROJECTS/TradingView/.venv/lib/python3.13/site-packages/urllib3/connectionpool.py", line 787, in urlopen
        response = self._make_request(
            conn,
        ...<10 lines>...
            **response_kw,
        )
      File "/Users/hmaheshwari/Documents/PROJECTS/TradingView/.venv/lib/python3.13/site-packages/urllib3/connectionpool.py", line 488, in _make_request
        raise new_e
      File "/Users/hmaheshwari/Documents/PROJECTS/TradingView/.venv/lib/python3.13/site-packages/urllib3/connectionpool.py", line 466, in _make_request
        self._raise_timeout(err=e, url=url, timeout_value=conn.timeout)
        ~~~~~~~~~~~~~~~~~~~^^^^^^^^^^^^^^^^^^^^^^^^^^^^^^^^^^^^^^^^^^^^
      File "/Users/hmaheshwari/Documents/PROJECTS/TradingView/.venv/lib/python3.13/site-packages/urllib3/connectionpool.py", line 367, in _raise_timeout
        raise ReadTimeoutError(
            self, url, f"Read timed out. (read timeout={timeout_value})"
        ) from err
    urllib3.exceptions.ReadTimeoutError: HTTPSConnectionPool(host='apiconnect.angelone.in', port=443): Read timed out. (read timeout=7)
    
    During handling of the above exception, another exception occurred:
    
    Traceback (most recent call last):
      File "/Users/hmaheshwari/Documents/PROJECTS/TradingView/backend/AngleSmartAPI.py", line 56, in get_data
        token_data = self.smartApi.searchScrip(exchange, symbol)
      File "/Users/hmaheshwari/Documents/PROJECTS/TradingView/.venv/lib/python3.13/site-packages/SmartApi/smartConnect.py", line 489, in searchScrip
        searchScripResult = self._postRequest("api.search.scrip", params)
      File "/Users/hmaheshwari/Documents/PROJECTS/TradingView/.venv/lib/python3.13/site-packages/SmartApi/smartConnect.py", line 263, in _postRequest
        return self._request(route, "POST", params)
               ~~~~~~~~~~~~~^^^^^^^^^^^^^^^^^^^^^^^
      File "/Users/hmaheshwari/Documents/PROJECTS/TradingView/.venv/lib/python3.13/site-packages/SmartApi/smartConnect.py", line 222, in _request
        raise e
      File "/Users/hmaheshwari/Documents/PROJECTS/TradingView/.venv/lib/python3.13/site-packages/SmartApi/smartConnect.py", line 210, in _request
        r = requests.request(method,
                                    url,
        ...<5 lines>...
                                    timeout=self.timeout,
                                    proxies=self.proxies)
      File "/Users/hmaheshwari/Documents/PROJECTS/TradingView/.venv/lib/python3.13/site-packages/requests/api.py", line 59, in request
        return session.request(method=method, url=url, **kwargs)
               ~~~~~~~~~~~~~~~^^^^^^^^^^^^^^^^^^^^^^^^^^^^^^^^^^
      File "/Users/hmaheshwari/Documents/PROJECTS/TradingView/.venv/lib/python3.13/site-packages/requests/sessions.py", line 589, in request
        resp = self.send(prep, **send_kwargs)
      File "/Users/hmaheshwari/Documents/PROJECTS/TradingView/.venv/lib/python3.13/site-packages/requests/sessions.py", line 703, in send
        r = adapter.send(request, **kwargs)
      File "/Users/hmaheshwari/Documents/PROJECTS/TradingView/.venv/lib/python3.13/site-packages/requests/adapters.py", line 713, in send
        raise ReadTimeout(e, request=request)
    requests.exceptions.ReadTimeout: HTTPSConnectionPool(host='apiconnect.angelone.in', port=443): Read timed out. (read timeout=7)
