[E 250917 18:54:35 AngleSmartAPI:74] Logout failed: list index out of range
    Traceback (most recent call last):
      File "/Users/hmaheshwari/Documents/Capstone PROJECTS/TradingView/backend/AngleSmartAPI.py", line 58, in get_data
        if not token_data or 'symboltoken' not in token_data["data"][0]:
                                                  ~~~~~~~~~~~~~~~~~~^^^
    IndexError: list index out of range
[E 250917 18:54:35 AngleSmartAPI:74] Logout failed: Couldn't parse the JSON response received from the server: b'Access denied because of exceeding access rate'
    Traceback (most recent call last):
      File "/Library/Frameworks/Python.framework/Versions/3.12/lib/python3.12/site-packages/SmartApi/smartConnect.py", line 230, in _request
        data = json.loads(r.content.decode("utf8"))
               ^^^^^^^^^^^^^^^^^^^^^^^^^^^^^^^^^^^^
      File "/Library/Frameworks/Python.framework/Versions/3.12/lib/python3.12/json/__init__.py", line 346, in loads
        return _default_decoder.decode(s)
               ^^^^^^^^^^^^^^^^^^^^^^^^^^
      File "/Library/Frameworks/Python.framework/Versions/3.12/lib/python3.12/json/decoder.py", line 337, in decode
        obj, end = self.raw_decode(s, idx=_w(s, 0).end())
                   ^^^^^^^^^^^^^^^^^^^^^^^^^^^^^^^^^^^^^^
      File "/Library/Frameworks/Python.framework/Versions/3.12/lib/python3.12/json/decoder.py", line 355, in raw_decode
        raise JSONDecodeError("Expecting value", s, err.value) from None
    json.decoder.JSONDecodeError: Expecting value: line 1 column 1 (char 0)
    
    During handling of the above exception, another exception occurred:
    
    Traceback (most recent call last):
      File "/Users/hmaheshwari/Documents/Capstone PROJECTS/TradingView/backend/AngleSmartAPI.py", line 56, in get_data
        token_data = self.smartApi.searchScrip(exchange, symbol)
                     ^^^^^^^^^^^^^^^^^^^^^^^^^^^^^^^^^^^^^^^^^^^
      File "/Library/Frameworks/Python.framework/Versions/3.12/lib/python3.12/site-packages/SmartApi/smartConnect.py", line 489, in searchScrip
        searchScripResult = self._postRequest("api.search.scrip", params)
                            ^^^^^^^^^^^^^^^^^^^^^^^^^^^^^^^^^^^^^^^^^^^^^
      File "/Library/Frameworks/Python.framework/Versions/3.12/lib/python3.12/site-packages/SmartApi/smartConnect.py", line 263, in _postRequest
        return self._request(route, "POST", params)
               ^^^^^^^^^^^^^^^^^^^^^^^^^^^^^^^^^^^^
      File "/Library/Frameworks/Python.framework/Versions/3.12/lib/python3.12/site-packages/SmartApi/smartConnect.py", line 233, in _request
        raise ex.DataException("Couldn't parse the JSON response received from the server: {content}".format(
    SmartApi.smartExceptions.DataException: Couldn't parse the JSON response received from the server: b'Access denied because of exceeding access rate'
[E 250917 18:54:58 AngleSmartAPI:74] Logout failed: list index out of range
    Traceback (most recent call last):
      File "/Users/hmaheshwari/Documents/Capstone PROJECTS/TradingView/backend/AngleSmartAPI.py", line 58, in get_data
        if not token_data or 'symboltoken' not in token_data["data"][0]:
                                                  ~~~~~~~~~~~~~~~~~~^^^
    IndexError: list index out of range
[E 250917 18:54:59 AngleSmartAPI:74] Logout failed: list index out of range
    Traceback (most recent call last):
      File "/Users/hmaheshwari/Documents/Capstone PROJECTS/TradingView/backend/AngleSmartAPI.py", line 58, in get_data
        if not token_data or 'symboltoken' not in token_data["data"][0]:
                                                  ~~~~~~~~~~~~~~~~~~^^^
    IndexError: list index out of range
[E 250917 19:05:29 AngleSmartAPI:74] Logout failed: list index out of range
    Traceback (most recent call last):
      File "/Users/hmaheshwari/Documents/Capstone PROJECTS/TradingView/backend/AngleSmartAPI.py", line 58, in get_data
        if not token_data or 'symboltoken' not in token_data["data"][0]:
                                                  ~~~~~~~~~~~~~~~~~~^^^
    IndexError: list index out of range
[E 250917 19:05:29 AngleSmartAPI:74] Logout failed: list index out of range
    Traceback (most recent call last):
      File "/Users/hmaheshwari/Documents/Capstone PROJECTS/TradingView/backend/AngleSmartAPI.py", line 58, in get_data
        if not token_data or 'symboltoken' not in token_data["data"][0]:
                                                  ~~~~~~~~~~~~~~~~~~^^^
    IndexError: list index out of range
[E 250917 19:05:32 AngleSmartAPI:74] Logout failed: list index out of range
    Traceback (most recent call last):
      File "/Users/hmaheshwari/Documents/Capstone PROJECTS/TradingView/backend/AngleSmartAPI.py", line 58, in get_data
        if not token_data or 'symboltoken' not in token_data["data"][0]:
                                                  ~~~~~~~~~~~~~~~~~~^^^
    IndexError: list index out of range
[E 250917 19:05:32 AngleSmartAPI:74] Logout failed: list index out of range
    Traceback (most recent call last):
      File "/Users/hmaheshwari/Documents/Capstone PROJECTS/TradingView/backend/AngleSmartAPI.py", line 58, in get_data
        if not token_data or 'symboltoken' not in token_data["data"][0]:
                                                  ~~~~~~~~~~~~~~~~~~^^^
    IndexError: list index out of range
[E 250917 19:09:19 smartConnect:221] Error occurred while making a POST request to https://apiconnect.angelone.in/rest/secure/angelbroking/historical/v1/getCandleData. Headers: {'Content-type': 'application/json', 'X-ClientLocalIP': '127.0.0.1', 'X-ClientPublicIP': '106.193.147.98', 'X-MACAddress': 'fa:15:15:31:b2:20', 'Accept': 'application/json', 'X-PrivateKey': 'vhAupRK9', 'X-UserType': 'USER', 'X-SourceID': 'WEB', 'Authorization': 'Bearer eyJhbGciOiJIUzUxMiJ9.eyJ1c2VybmFtZSI6Ikw1MjEyODY3MyIsInJvbGVzIjowLCJ1c2VydHlwZSI6IlVTRVIiLCJ0b2tlbiI6ImV5SmhiR2NpT2lKU1V6STFOaUlzSW5SNWNDSTZJa3BYVkNKOS5leUoxYzJWeVgzUjVjR1VpT2lKamJHbGxiblFpTENKMGIydGxibDkwZVhCbElqb2lkSEpoWkdWZllXTmpaWE56WDNSdmEyVnVJaXdpWjIxZmFXUWlPakV5TENKemIzVnlZMlVpT2lJeklpd2laR1YyYVdObFgybGtJam9pTjJNMk56STVaV1l0T1dFd1lTMHpNakF6TFRneFpHWXROVGczWTJNM05qUmtaRGcySWl3aWEybGtJam9pZEhKaFpHVmZhMlY1WDNZeUlpd2liMjF1WlcxaGJtRm5aWEpwWkNJNk1USXNJbkJ5YjJSMVkzUnpJanA3SW1SbGJXRjBJanA3SW5OMFlYUjFjeUk2SW1GamRHbDJaU0o5TENKdFppSTZleUp6ZEdGMGRYTWlPaUpoWTNScGRtVWlmWDBzSW1semN5STZJblJ5WVdSbFgyeHZaMmx1WDNObGNuWnBZMlVpTENKemRXSWlPaUpNTlRJeE1qZzJOek1pTENKbGVIQWlPakUzTlRneU1ESTNOREFzSW01aVppSTZNVGMxT0RFeE5qRTJNQ3dpYVdGMElqb3hOelU0TVRFMk1UWXdMQ0pxZEdraU9pSXdZMk0xTVdZMU5DMHpOalZpTFRRellUQXRPVE0xTnkweU5qWXdPVFppTW1NeVlUTWlMQ0pVYjJ0bGJpSTZJaUo5LmtPY0U5NVJRUEdVWnJBQlNxNG5TZHAtd3ZYTGxRRWVpUTRGU2NNZXZYWmg4el9kS0lEaHNCYjVyMHEyT1ZScjlVS2VtVEk0MmU4ZlpwNDVOSmhJdVo3eTBtRHpzV1FFVHM0cE82NEt6WXBhVk9aLUpMTHlQY1YwVUtsZUdpQlNYR0dpbzNhY1RiQUVmVGVZZDdYX1JhT2xCZDVOcGV2WTFJcEU3a1V3aUl6RSIsIkFQSS1LRVkiOiJ2aEF1cFJLOSIsImlhdCI6MTc1ODExNjM0MSwiZXhwIjoxNzU4MTMzODAwfQ.p7HN-83rCPOC-dBvmx-OqpYybbLDPx2ZMiZBr7oCiPQyMTkHcyBmx4cHanbil2Lc655KqqymPdtO4jiWN8JGsg'}, Request: {'exchange': 'NSE', 'symboltoken': '3045', 'interval': 'ONE_HOUR', 'fromdate': '2024-12-17 09:00', 'todate': '2025-03-17 09:16'}, Response: HTTPSConnectionPool(host='apiconnect.angelone.in', port=443): Max retries exceeded with url: /rest/secure/angelbroking/historical/v1/getCandleData (Caused by SSLError(SSLEOFError(8, '[SSL: UNEXPECTED_EOF_WHILE_READING] EOF occurred in violation of protocol (_ssl.c:1000)')))
[E 250917 19:09:19 AngleSmartAPI:74] Logout failed: HTTPSConnectionPool(host='apiconnect.angelone.in', port=443): Max retries exceeded with url: /rest/secure/angelbroking/historical/v1/getCandleData (Caused by SSLError(SSLEOFError(8, '[SSL: UNEXPECTED_EOF_WHILE_READING] EOF occurred in violation of protocol (_ssl.c:1000)')))
    Traceback (most recent call last):
      File "/Library/Frameworks/Python.framework/Versions/3.12/lib/python3.12/site-packages/urllib3/connectionpool.py", line 467, in _make_request
        self._validate_conn(conn)
      File "/Library/Frameworks/Python.framework/Versions/3.12/lib/python3.12/site-packages/urllib3/connectionpool.py", line 1092, in _validate_conn
        conn.connect()
      File "/Library/Frameworks/Python.framework/Versions/3.12/lib/python3.12/site-packages/urllib3/connection.py", line 635, in connect
        sock_and_verified = _ssl_wrap_socket_and_match_hostname(
                            ^^^^^^^^^^^^^^^^^^^^^^^^^^^^^^^^^^^^
      File "/Library/Frameworks/Python.framework/Versions/3.12/lib/python3.12/site-packages/urllib3/connection.py", line 776, in _ssl_wrap_socket_and_match_hostname
        ssl_sock = ssl_wrap_socket(
                   ^^^^^^^^^^^^^^^^
      File "/Library/Frameworks/Python.framework/Versions/3.12/lib/python3.12/site-packages/urllib3/util/ssl_.py", line 466, in ssl_wrap_socket
        ssl_sock = _ssl_wrap_socket_impl(sock, context, tls_in_tls, server_hostname)
                   ^^^^^^^^^^^^^^^^^^^^^^^^^^^^^^^^^^^^^^^^^^^^^^^^^^^^^^^^^^^^^^^^^
      File "/Library/Frameworks/Python.framework/Versions/3.12/lib/python3.12/site-packages/urllib3/util/ssl_.py", line 510, in _ssl_wrap_socket_impl
        return ssl_context.wrap_socket(sock, server_hostname=server_hostname)
               ^^^^^^^^^^^^^^^^^^^^^^^^^^^^^^^^^^^^^^^^^^^^^^^^^^^^^^^^^^^^^^
      File "/Library/Frameworks/Python.framework/Versions/3.12/lib/python3.12/ssl.py", line 455, in wrap_socket
        return self.sslsocket_class._create(
               ^^^^^^^^^^^^^^^^^^^^^^^^^^^^^
      File "/Library/Frameworks/Python.framework/Versions/3.12/lib/python3.12/ssl.py", line 1042, in _create
        self.do_handshake()
      File "/Library/Frameworks/Python.framework/Versions/3.12/lib/python3.12/ssl.py", line 1320, in do_handshake
        self._sslobj.do_handshake()
    ssl.SSLEOFError: [SSL: UNEXPECTED_EOF_WHILE_READING] EOF occurred in violation of protocol (_ssl.c:1000)
    
    During handling of the above exception, another exception occurred:
    
    Traceback (most recent call last):
      File "/Library/Frameworks/Python.framework/Versions/3.12/lib/python3.12/site-packages/urllib3/connectionpool.py", line 790, in urlopen
        response = self._make_request(
                   ^^^^^^^^^^^^^^^^^^^
      File "/Library/Frameworks/Python.framework/Versions/3.12/lib/python3.12/site-packages/urllib3/connectionpool.py", line 491, in _make_request
        raise new_e
    urllib3.exceptions.SSLError: [SSL: UNEXPECTED_EOF_WHILE_READING] EOF occurred in violation of protocol (_ssl.c:1000)
    
    The above exception was the direct cause of the following exception:
    
    Traceback (most recent call last):
      File "/Library/Frameworks/Python.framework/Versions/3.12/lib/python3.12/site-packages/requests/adapters.py", line 486, in send
        resp = conn.urlopen(
               ^^^^^^^^^^^^^
      File "/Library/Frameworks/Python.framework/Versions/3.12/lib/python3.12/site-packages/urllib3/connectionpool.py", line 844, in urlopen
        retries = retries.increment(
                  ^^^^^^^^^^^^^^^^^^
      File "/Library/Frameworks/Python.framework/Versions/3.12/lib/python3.12/site-packages/urllib3/util/retry.py", line 515, in increment
        raise MaxRetryError(_pool, url, reason) from reason  # type: ignore[arg-type]
        ^^^^^^^^^^^^^^^^^^^^^^^^^^^^^^^^^^^^^^^^^^^^^^^^^^^
    urllib3.exceptions.MaxRetryError: HTTPSConnectionPool(host='apiconnect.angelone.in', port=443): Max retries exceeded with url: /rest/secure/angelbroking/historical/v1/getCandleData (Caused by SSLError(SSLEOFError(8, '[SSL: UNEXPECTED_EOF_WHILE_READING] EOF occurred in violation of protocol (_ssl.c:1000)')))
    
    During handling of the above exception, another exception occurred:
    
    Traceback (most recent call last):
      File "/Users/hmaheshwari/Documents/Capstone PROJECTS/TradingView/backend/AngleSmartAPI.py", line 71, in get_data
        hist = self.smartApi.getCandleData(historicParam)
               ^^^^^^^^^^^^^^^^^^^^^^^^^^^^^^^^^^^^^^^^^^
      File "/Library/Frameworks/Python.framework/Versions/3.12/lib/python3.12/site-packages/SmartApi/smartConnect.py", line 465, in getCandleData
        getCandleDataResponse=self._postRequest("api.candle.data",historicDataParams)
                              ^^^^^^^^^^^^^^^^^^^^^^^^^^^^^^^^^^^^^^^^^^^^^^^^^^^^^^^
      File "/Library/Frameworks/Python.framework/Versions/3.12/lib/python3.12/site-packages/SmartApi/smartConnect.py", line 263, in _postRequest
        return self._request(route, "POST", params)
               ^^^^^^^^^^^^^^^^^^^^^^^^^^^^^^^^^^^^
      File "/Library/Frameworks/Python.framework/Versions/3.12/lib/python3.12/site-packages/SmartApi/smartConnect.py", line 222, in _request
        raise e
      File "/Library/Frameworks/Python.framework/Versions/3.12/lib/python3.12/site-packages/SmartApi/smartConnect.py", line 210, in _request
        r = requests.request(method,
            ^^^^^^^^^^^^^^^^^^^^^^^^
      File "/Library/Frameworks/Python.framework/Versions/3.12/lib/python3.12/site-packages/requests/api.py", line 59, in request
        return session.request(method=method, url=url, **kwargs)
               ^^^^^^^^^^^^^^^^^^^^^^^^^^^^^^^^^^^^^^^^^^^^^^^^^
      File "/Library/Frameworks/Python.framework/Versions/3.12/lib/python3.12/site-packages/requests/sessions.py", line 589, in request
        resp = self.send(prep, **send_kwargs)
               ^^^^^^^^^^^^^^^^^^^^^^^^^^^^^^
      File "/Library/Frameworks/Python.framework/Versions/3.12/lib/python3.12/site-packages/requests/sessions.py", line 703, in send
        r = adapter.send(request, **kwargs)
            ^^^^^^^^^^^^^^^^^^^^^^^^^^^^^^^
      File "/Library/Frameworks/Python.framework/Versions/3.12/lib/python3.12/site-packages/requests/adapters.py", line 517, in send
        raise SSLError(e, request=request)
    requests.exceptions.SSLError: HTTPSConnectionPool(host='apiconnect.angelone.in', port=443): Max retries exceeded with url: /rest/secure/angelbroking/historical/v1/getCandleData (Caused by SSLError(SSLEOFError(8, '[SSL: UNEXPECTED_EOF_WHILE_READING] EOF occurred in violation of protocol (_ssl.c:1000)')))
[E 250917 19:10:23 smartConnect:221] Error occurred while making a POST request to https://apiconnect.angelone.in/rest/secure/angelbroking/order/v1/searchScrip. Headers: {'Content-type': 'application/json', 'X-ClientLocalIP': '127.0.0.1', 'X-ClientPublicIP': '106.193.147.98', 'X-MACAddress': 'fa:15:15:31:b2:20', 'Accept': 'application/json', 'X-PrivateKey': 'vhAupRK9', 'X-UserType': 'USER', 'X-SourceID': 'WEB', 'Authorization': 'Bearer eyJhbGciOiJIUzUxMiJ9.eyJ1c2VybmFtZSI6Ikw1MjEyODY3MyIsInJvbGVzIjowLCJ1c2VydHlwZSI6IlVTRVIiLCJ0b2tlbiI6ImV5SmhiR2NpT2lKU1V6STFOaUlzSW5SNWNDSTZJa3BYVkNKOS5leUoxYzJWeVgzUjVjR1VpT2lKamJHbGxiblFpTENKMGIydGxibDkwZVhCbElqb2lkSEpoWkdWZllXTmpaWE56WDNSdmEyVnVJaXdpWjIxZmFXUWlPakV5TENKemIzVnlZMlVpT2lJeklpd2laR1YyYVdObFgybGtJam9pTjJNMk56STVaV1l0T1dFd1lTMHpNakF6TFRneFpHWXROVGczWTJNM05qUmtaRGcySWl3aWEybGtJam9pZEhKaFpHVmZhMlY1WDNZeUlpd2liMjF1WlcxaGJtRm5aWEpwWkNJNk1USXNJbkJ5YjJSMVkzUnpJanA3SW1SbGJXRjBJanA3SW5OMFlYUjFjeUk2SW1GamRHbDJaU0o5TENKdFppSTZleUp6ZEdGMGRYTWlPaUpoWTNScGRtVWlmWDBzSW1semN5STZJblJ5WVdSbFgyeHZaMmx1WDNObGNuWnBZMlVpTENKemRXSWlPaUpNTlRJeE1qZzJOek1pTENKbGVIQWlPakUzTlRneU1ESTNOellzSW01aVppSTZNVGMxT0RFeE5qRTVOaXdpYVdGMElqb3hOelU0TVRFMk1UazJMQ0pxZEdraU9pSmpNekU0TnprMU5DMDNPRFl5TFRRNU1EQXRPRE01WkMwMll6azRPR1ZqTURFeFpXSWlMQ0pVYjJ0bGJpSTZJaUo5LkprNWxzSE5DZ0lscno0MDhXcEFUQjZrS0dSVGgzM3k4eEtWMnVYdUREUjFrRWI2bS1xZnVsUlY1Zmotc3V6VDhvc3E1eWl3MzRIaWFoNFFSYlQ2cXlQWXFUTy1xdHAwa2k5YnRDUE51VGpxbENtaHhuR0NUN3U3NTJscW9NVkRvUWFmUTdIdThXRmFkN2xaUW44Z1NsNjVZRm9VR2dyc2ExT201RHB3RG5INCIsIkFQSS1LRVkiOiJ2aEF1cFJLOSIsImlhdCI6MTc1ODExNjM3NywiZXhwIjoxNzU4MTMzODAwfQ.qnZPtzCDFeQnPkwzoHpDbLz3Z9f-eH6RCd3Y1uXrDUWxLlg6-GDf8ysRX46FXdeyT-SzIMvA17OeUvMnHsjDPw'}, Request: {'exchange': 'NSE', 'searchscrip': 'SBIN-EQ'}, Response: HTTPSConnectionPool(host='apiconnect.angelone.in', port=443): Max retries exceeded with url: /rest/secure/angelbroking/order/v1/searchScrip (Caused by ConnectTimeoutError(<urllib3.connection.HTTPSConnection object at 0x13d613680>, 'Connection to apiconnect.angelone.in timed out. (connect timeout=7)'))
[E 250917 19:10:23 AngleSmartAPI:74] Logout failed: HTTPSConnectionPool(host='apiconnect.angelone.in', port=443): Max retries exceeded with url: /rest/secure/angelbroking/order/v1/searchScrip (Caused by ConnectTimeoutError(<urllib3.connection.HTTPSConnection object at 0x13d613680>, 'Connection to apiconnect.angelone.in timed out. (connect timeout=7)'))
    Traceback (most recent call last):
      File "/Library/Frameworks/Python.framework/Versions/3.12/lib/python3.12/site-packages/urllib3/connection.py", line 200, in _new_conn
        sock = connection.create_connection(
               ^^^^^^^^^^^^^^^^^^^^^^^^^^^^^
      File "/Library/Frameworks/Python.framework/Versions/3.12/lib/python3.12/site-packages/urllib3/util/connection.py", line 85, in create_connection
        raise err
      File "/Library/Frameworks/Python.framework/Versions/3.12/lib/python3.12/site-packages/urllib3/util/connection.py", line 73, in create_connection
        sock.connect(sa)
    TimeoutError: timed out
    
    The above exception was the direct cause of the following exception:
    
    Traceback (most recent call last):
      File "/Library/Frameworks/Python.framework/Versions/3.12/lib/python3.12/site-packages/urllib3/connectionpool.py", line 790, in urlopen
        response = self._make_request(
                   ^^^^^^^^^^^^^^^^^^^
      File "/Library/Frameworks/Python.framework/Versions/3.12/lib/python3.12/site-packages/urllib3/connectionpool.py", line 491, in _make_request
        raise new_e
      File "/Library/Frameworks/Python.framework/Versions/3.12/lib/python3.12/site-packages/urllib3/connectionpool.py", line 467, in _make_request
        self._validate_conn(conn)
      File "/Library/Frameworks/Python.framework/Versions/3.12/lib/python3.12/site-packages/urllib3/connectionpool.py", line 1092, in _validate_conn
        conn.connect()
      File "/Library/Frameworks/Python.framework/Versions/3.12/lib/python3.12/site-packages/urllib3/connection.py", line 604, in connect
        self.sock = sock = self._new_conn()
                           ^^^^^^^^^^^^^^^^
      File "/Library/Frameworks/Python.framework/Versions/3.12/lib/python3.12/site-packages/urllib3/connection.py", line 209, in _new_conn
        raise ConnectTimeoutError(
    urllib3.exceptions.ConnectTimeoutError: (<urllib3.connection.HTTPSConnection object at 0x13d613680>, 'Connection to apiconnect.angelone.in timed out. (connect timeout=7)')
    
    The above exception was the direct cause of the following exception:
    
    Traceback (most recent call last):
      File "/Library/Frameworks/Python.framework/Versions/3.12/lib/python3.12/site-packages/requests/adapters.py", line 486, in send
        resp = conn.urlopen(
               ^^^^^^^^^^^^^
      File "/Library/Frameworks/Python.framework/Versions/3.12/lib/python3.12/site-packages/urllib3/connectionpool.py", line 844, in urlopen
        retries = retries.increment(
                  ^^^^^^^^^^^^^^^^^^
      File "/Library/Frameworks/Python.framework/Versions/3.12/lib/python3.12/site-packages/urllib3/util/retry.py", line 515, in increment
        raise MaxRetryError(_pool, url, reason) from reason  # type: ignore[arg-type]
        ^^^^^^^^^^^^^^^^^^^^^^^^^^^^^^^^^^^^^^^^^^^^^^^^^^^
    urllib3.exceptions.MaxRetryError: HTTPSConnectionPool(host='apiconnect.angelone.in', port=443): Max retries exceeded with url: /rest/secure/angelbroking/order/v1/searchScrip (Caused by ConnectTimeoutError(<urllib3.connection.HTTPSConnection object at 0x13d613680>, 'Connection to apiconnect.angelone.in timed out. (connect timeout=7)'))
    
    During handling of the above exception, another exception occurred:
    
    Traceback (most recent call last):
      File "/Users/hmaheshwari/Documents/Capstone PROJECTS/TradingView/backend/AngleSmartAPI.py", line 56, in get_data
        token_data = self.smartApi.searchScrip(exchange, symbol)
                     ^^^^^^^^^^^^^^^^^^^^^^^^^^^^^^^^^^^^^^^^^^^
      File "/Library/Frameworks/Python.framework/Versions/3.12/lib/python3.12/site-packages/SmartApi/smartConnect.py", line 489, in searchScrip
        searchScripResult = self._postRequest("api.search.scrip", params)
                            ^^^^^^^^^^^^^^^^^^^^^^^^^^^^^^^^^^^^^^^^^^^^^
      File "/Library/Frameworks/Python.framework/Versions/3.12/lib/python3.12/site-packages/SmartApi/smartConnect.py", line 263, in _postRequest
        return self._request(route, "POST", params)
               ^^^^^^^^^^^^^^^^^^^^^^^^^^^^^^^^^^^^
      File "/Library/Frameworks/Python.framework/Versions/3.12/lib/python3.12/site-packages/SmartApi/smartConnect.py", line 222, in _request
        raise e
      File "/Library/Frameworks/Python.framework/Versions/3.12/lib/python3.12/site-packages/SmartApi/smartConnect.py", line 210, in _request
        r = requests.request(method,
            ^^^^^^^^^^^^^^^^^^^^^^^^
      File "/Library/Frameworks/Python.framework/Versions/3.12/lib/python3.12/site-packages/requests/api.py", line 59, in request
        return session.request(method=method, url=url, **kwargs)
               ^^^^^^^^^^^^^^^^^^^^^^^^^^^^^^^^^^^^^^^^^^^^^^^^^
      File "/Library/Frameworks/Python.framework/Versions/3.12/lib/python3.12/site-packages/requests/sessions.py", line 589, in request
        resp = self.send(prep, **send_kwargs)
               ^^^^^^^^^^^^^^^^^^^^^^^^^^^^^^
      File "/Library/Frameworks/Python.framework/Versions/3.12/lib/python3.12/site-packages/requests/sessions.py", line 703, in send
        r = adapter.send(request, **kwargs)
            ^^^^^^^^^^^^^^^^^^^^^^^^^^^^^^^
      File "/Library/Frameworks/Python.framework/Versions/3.12/lib/python3.12/site-packages/requests/adapters.py", line 507, in send
        raise ConnectTimeout(e, request=request)
    requests.exceptions.ConnectTimeout: HTTPSConnectionPool(host='apiconnect.angelone.in', port=443): Max retries exceeded with url: /rest/secure/angelbroking/order/v1/searchScrip (Caused by ConnectTimeoutError(<urllib3.connection.HTTPSConnection object at 0x13d613680>, 'Connection to apiconnect.angelone.in timed out. (connect timeout=7)'))
[E 250917 19:10:23 smartConnect:221] Error occurred while making a POST request to https://apiconnect.angelone.in/rest/auth/angelbroking/user/v1/loginByPassword. Headers: {'Content-type': 'application/json', 'X-ClientLocalIP': '127.0.0.1', 'X-ClientPublicIP': '106.193.147.98', 'X-MACAddress': 'fa:15:15:31:b2:20', 'Accept': 'application/json', 'X-PrivateKey': 'vhAupRK9', 'X-UserType': 'USER', 'X-SourceID': 'WEB'}, Request: {'clientcode': 'L52128673', 'password': '7990', 'totp': '280052'}, Response: HTTPSConnectionPool(host='apiconnect.angelone.in', port=443): Max retries exceeded with url: /rest/auth/angelbroking/user/v1/loginByPassword (Caused by NameResolutionError("<urllib3.connection.HTTPSConnection object at 0x13d610fb0>: Failed to resolve 'apiconnect.angelone.in' ([Errno 8] nodename nor servname provided, or not known)"))
